<?xml version="1.0" encoding="utf-8"?>

<robot xmlns:xacro="http://wiki.ros.org/xacro">
  <xacro:macro name="arm" params="parent child xyz rpy">
  
  <link
    name="base_link">
    <inertial>
      <origin
        xyz="0.00094697 -0.0015923 0.017039"
        rpy="0 0 0" />
      <mass
        value="0.9895" />
      <inertia
        ixx="0.0024052"
        ixy="-1.6224E-06"
        ixz="-7.1964E-06"
        iyy="0.0022932"
        iyz="4.4872E-06"
        izz="0.0043883" />
    </inertial>
    <visual>
      <origin
        xyz="0 0 0"
        rpy="0 0 0" />
      <geometry>
        <mesh
          filename="package://assembled_urdf/meshes/base_link.STL" />
      </geometry>
      <material
        name="">
        <color
          rgba="0.75294 0.75294 0.75294 1" />
      </material>
    </visual>
    <collision>
      <origin
        xyz="0 0 0"
        rpy="0 0 0" />
      <geometry>
        <mesh
          filename="package://assembled_urdf/meshes/base_link.STL" />
      </geometry>
    </collision>
  </link>
  <link
    name="Link_1">
    <inertial>
      <origin
        xyz="0.0062012 -0.0010396 0.07345"
        rpy="0 0 0" />
      <mass
        value="2.3704" />
      <inertia
        ixx="0.0063333"
        ixy="3.9221E-05"
        ixz="-0.00018614"
        iyy="0.0065654"
        iyz="2.9878E-05"
        izz="0.0074695" />
    </inertial>
    <visual>
      <origin
        xyz="0 0 0"
        rpy="0 0 0" />
      <geometry>
        <mesh
          filename="package://assembled_urdf/meshes/Link_1.STL" />
      </geometry>
      <material
        name="">
        <color
          rgba="0.75294 0.75294 0.75294 1" />
      </material>
    </visual>
    <collision>
      <origin
        xyz="0 0 0"
        rpy="0 0 0" />
      <geometry>
        <mesh
          filename="package://assembled_urdf/meshes/Link_1.STL" />
      </geometry>
    </collision>
  </link>
  <joint
    name="Joint_1"
    type="continuous">
    <origin
      xyz="0 0 0.033"
      rpy="0 0 0" />
    <parent
      link="base_link" />
    <child
      link="Link_1" />
    <axis
      xyz="0 0 1" />
  </joint>
  <link
    name="Link_2">
    <inertial>
      <origin
        xyz="0.074309 -0.025678 0.24799"
        rpy="0 0 0" />
      <mass
        value="6.3176" />
      <inertia
        ixx="0.074903"
        ixy="-0.00018915"
        ixz="0.00038877"
        iyy="0.073765"
        iyz="0.003007"
        izz="0.015713" />
    </inertial>
    <visual>
      <origin
        xyz="0 0 0"
        rpy="0 0 0" />
      <geometry>
        <mesh
          filename="package://assembled_urdf/meshes/Link_2.STL" />
      </geometry>
      <material
        name="">
        <color
          rgba="0.75294 0.75294 0.75294 1" />
      </material>
    </visual>
    <collision>
      <origin
        xyz="0 0 0"
        rpy="0 0 0" />
      <geometry>
        <mesh
          filename="package://assembled_urdf/meshes/Link_2.STL" />
      </geometry>
    </collision>
  </link>
  <joint
    name="Joint_2"
    type="continuous">
    <origin
      xyz="0.079086 -0.013406 0.087"
      rpy="0 0 0" />
    <parent
      link="Link_1" />
    <child
      link="Link_2" />
    <axis
      xyz="0.98594 -0.16713 0" />
  </joint>
  <link
    name="Link_3">
    <inertial>
      <origin
        xyz="-0.052097 0.0088396 0.21874"
        rpy="0 0 0" />
      <mass
        value="3.5336" />
      <inertia
        ixx="0.046389"
        ixy="-0.0001322"
        ixz="-2.5465E-05"
        iyy="0.045634"
        iyz="4.485E-06"
        izz="0.0043018" />
    </inertial>
    <visual>
      <origin
        xyz="0 0 0"
        rpy="0 0 0" />
      <geometry>
        <mesh
          filename="package://assembled_urdf/meshes/Link_3.STL" />
      </geometry>
      <material
        name="">
        <color
          rgba="0.75294 0.75294 0.75294 1" />
      </material>
    </visual>
    <collision>
      <origin
        xyz="0 0 0"
        rpy="0 0 0" />
      <geometry>
        <mesh
          filename="package://assembled_urdf/meshes/Link_3.STL" />
      </geometry>
    </collision>
  </link>
  <joint
    name="Joint_3"
    type="continuous">
    <origin
      xyz="0.005921 -0.033198 0.61017"
      rpy="0 0 0" />
    <parent
      link="Link_2" />
    <child
      link="Link_3" />
    <axis
     xyz="0.98594 -0.16713 0" />
  </joint>
  <link
    name="Link_4">
    <inertial>
      <origin
        xyz="0.050272 -0.008521 0.006048"
        rpy="0 0 0" />
      <mass
        value="0.47956" />
      <inertia
        ixx="0.00047621"
        ixy="3.596E-06"
        ixz="-6.8422E-06"
        iyy="0.00049705"
        iyz="1.2048E-06"
        izz="0.00051651" />
    </inertial>
    <visual>
      <origin
        xyz="0 0 0"
        rpy="0 0 0" />
      <geometry>
        <mesh
          filename="package://assembled_urdf/meshes/Link_4.STL" />
      </geometry>
      <material
        name="">
        <color
          rgba="0.75294 0.75294 0.75294 1" />
      </material>
    </visual>
    <collision>
      <origin
        xyz="0 0 0"
        rpy="0 0 0" />
      <geometry>
        <mesh
          filename="package://assembled_urdf/meshes/Link_4.STL" />
      </geometry>
    </collision>
  </link>
  <joint
    name="Joint_4"
    type="continuous">
    <origin
      xyz="-0.015676 0.0026573 0.59"
      rpy="0 0 0" />
    <parent
      link="Link_3" />
    <child
      link="Link_4" />
    <axis
      xyz="0.98594 -0.16713 0" />
  </joint>
  <link
    name="Link_5">
    <inertial>
      <origin
        xyz="0.0059628 -0.0010115 0.050989"
        rpy="0 0 0" />
      <mass
        value="0.47956" />
      <inertia
        ixx="0.00051596"
        ixy="-3.148E-06"
        ixz="-6.8429E-06"
        iyy="0.0004982"
        iyz="1.1992E-06"
        izz="0.00047561" />
    </inertial>
    <visual>
      <origin
        xyz="0 0 0"
        rpy="0 0 0" />
      <geometry>
        <mesh
          filename="package://assembled_urdf/meshes/Link_5.STL" />
      </geometry>
      <material
        name="">
        <color
          rgba="0.75294 0.75294 0.75294 1" />
      </material>
    </visual>
    <collision>
      <origin
        xyz="0 0 0"
        rpy="0 0 0" />
      <geometry>
        <mesh
          filename="package://assembled_urdf/meshes/Link_5.STL" />
      </geometry>
    </collision>
  </link>
  <joint
    name="Joint_5"
    type="continuous">
    <origin
      xyz="0.053733 -0.0091084 0.0425"
      rpy="0 0 0" />
    <parent
      link="Link_4" />
    <child
      link="Link_5" />
    <axis
      xyz="0.98594 -0.16713 0" />
  </joint>
  <link
    name="Link_6">
    <inertial>
      <origin
        xyz="0.0092118 -0.0020342 0.0013291"
        rpy="0 0 0" />
      <mass
        value="0.28074" />
      <inertia
        ixx="0.00029014"
        ixy="-2.1501E-05"
        ixz="-1.3549E-06"
        iyy="0.00016562"
        iyz="-4.266E-06"
        izz="0.0001731" />
    </inertial>
    <visual>
      <origin
        xyz="0 0 0"
        rpy="0 0 0" />
      <geometry>
        <mesh
          filename="package://assembled_urdf/meshes/Link_6.STL" />
      </geometry>
      <material
        name="">
        <color
          rgba="0.75294 0.75294 0.75294 1" />
      </material>
    </visual>
    <collision>
      <origin
        xyz="0 0 0"
        rpy="0 0 0" />
      <geometry>
        <mesh
          filename="package://assembled_urdf/meshes/Link_6.STL" />
      </geometry>
    </collision>
  </link>
  <joint
    name="Joint_6"
    type="continuous">
    <origin
      xyz="0.053241 -0.0090248 0.0545"
      rpy="0 0 0" />
    <parent
      link="Link_5" />
    <child
      link="Link_6" />
    <axis
      xyz="-0.98594 0.16713 0" />
  </joint>
  </xacro:macro>
</robot>
